============================= test session starts ==============================
platform darwin -- Python 3.11.5, pytest-8.3.5, pluggy-1.6.0
rootdir: /Users/Sharrone/Visual_DM/backend
configfile: pyproject.toml
plugins: anyio-4.9.0, mock-3.14.0, cov-6.1.1
collected 85 items / 10 errors / 28 skipped

==================================== ERRORS ====================================
___ ERROR collecting app/src/core/visualdm_core/tests/test_cloud_storage.py ____
ImportError while importing test module '/Users/Sharrone/Visual_DM/backend/app/src/core/visualdm_core/tests/test_cloud_storage.py'.
Hint: make sure your test modules/packages have valid Python names.
Traceback:
../.pyenv/versions/3.11.5/lib/python3.11/importlib/__init__.py:126: in import_module
    return _bootstrap._gcd_import(name[level:], package, level)
backend/app/src/core/visualdm_core/tests/test_cloud_storage.py:4: in <module>
    from visualdm_core.cloud_storage import CloudStorage
E   ModuleNotFoundError: No module named 'visualdm_core'
_______________ ERROR collecting app/world/tests/test_region.py ________________
ImportError while importing test module '/Users/Sharrone/Visual_DM/backend/app/world/tests/test_region.py'.
Hint: make sure your test modules/packages have valid Python names.
Traceback:
../.pyenv/versions/3.11.5/lib/python3.11/importlib/__init__.py:126: in import_module
    return _bootstrap._gcd_import(name[level:], package, level)
backend/app/world/tests/test_region.py:9: in <module>
    from region_generation_utils import generate_region, log_region_event, summarize_region_memory
E   ModuleNotFoundError: No module named 'region_generation_utils'
___________ ERROR collecting combat/tests/test_damage_composition.py ___________
ImportError while importing test module '/Users/Sharrone/Visual_DM/backend/combat/tests/test_damage_composition.py'.
Hint: make sure your test modules/packages have valid Python names.
Traceback:
../.pyenv/versions/3.11.5/lib/python3.11/importlib/__init__.py:126: in import_module
    return _bootstrap._gcd_import(name[level:], package, level)
backend/combat/tests/test_damage_composition.py:3: in <module>
    from app.core.enums import DamageType
E   ModuleNotFoundError: No module named 'app'
______ ERROR collecting core/managers/tests/test_robust_scene_manager.py _______
ImportError while importing test module '/Users/Sharrone/Visual_DM/backend/core/managers/tests/test_robust_scene_manager.py'.
Hint: make sure your test modules/packages have valid Python names.
Traceback:
../.pyenv/versions/3.11.5/lib/python3.11/importlib/__init__.py:126: in import_module
    return _bootstrap._gcd_import(name[level:], package, level)
backend/core/managers/tests/test_robust_scene_manager.py:19: in <module>
    from visual_client.core.managers.robust_scene_manager import RobustSceneManager
E   ModuleNotFoundError: No module named 'visual_client'
------------------------------- Captured stdout --------------------------------
pygame 2.6.1 (SDL 2.28.4, Python 3.11.5)
Hello from the pygame community. https://www.pygame.org/contribute.html
____________ ERROR collecting core2/models/test_item_attributes.py _____________
ImportError while importing test module '/Users/Sharrone/Visual_DM/backend/core2/models/test_item_attributes.py'.
Hint: make sure your test modules/packages have valid Python names.
Traceback:
../.pyenv/versions/3.11.5/lib/python3.11/importlib/__init__.py:126: in import_module
    return _bootstrap._gcd_import(name[level:], package, level)
backend/core2/models/__init__.py:10: in <module>
    from app.core.models.base import BaseModel
E   ModuleNotFoundError: No module named 'app'
_ ERROR collecting python_converted/src/worldgen/core/test_deterministic_rng.py _
ImportError while importing test module '/Users/Sharrone/Visual_DM/backend/python_converted/src/worldgen/core/test_deterministic_rng.py'.
Hint: make sure your test modules/packages have valid Python names.
Traceback:
../.pyenv/versions/3.11.5/lib/python3.11/importlib/__init__.py:126: in import_module
    return _bootstrap._gcd_import(name[level:], package, level)
backend/python_converted/src/worldgen/__init__.py:32: in <module>
    from .region import *
backend/python_converted/src/worldgen/region/__init__.py:11: in <module>
    from python_converted.src.worldgen.region.BaseRegionGenerator import BaseRegionGenerator
E   ModuleNotFoundError: No module named 'python_converted'
_ ERROR collecting python_converted/src/worldgen/environment/__tests__/test_biome_transitions.py _
ImportError while importing test module '/Users/Sharrone/Visual_DM/backend/python_converted/src/worldgen/environment/__tests__/test_biome_transitions.py'.
Hint: make sure your test modules/packages have valid Python names.
Traceback:
../.pyenv/versions/3.11.5/lib/python3.11/importlib/__init__.py:126: in import_module
    return _bootstrap._gcd_import(name[level:], package, level)
backend/python_converted/src/worldgen/environment/__tests__/test_biome_transitions.py:12: in <module>
    from ..BiomeTypes import BiomeType, BIOME_PARAMETERS, TRANSITION_BIOMES
E   ImportError: attempted relative import with no known parent package
_____________ ERROR collecting regions/test_region_revolt_utils.py _____________
ImportError while importing test module '/Users/Sharrone/Visual_DM/backend/regions/test_region_revolt_utils.py'.
Hint: make sure your test modules/packages have valid Python names.
Traceback:
../.pyenv/versions/3.11.5/lib/python3.11/importlib/__init__.py:126: in import_module
    return _bootstrap._gcd_import(name[level:], package, level)
backend/regions/__init__.py:22: in <module>
    from app.regions.tension_utils import (
E   ModuleNotFoundError: No module named 'app.regions.tension_utils'
_____________ ERROR collecting tests/test_coordinate_validation.py _____________
ImportError while importing test module '/Users/Sharrone/Visual_DM/backend/tests/test_coordinate_validation.py'.
Hint: make sure your test modules/packages have valid Python names.
Traceback:
../.pyenv/versions/3.11.5/lib/python3.11/importlib/__init__.py:126: in import_module
    return _bootstrap._gcd_import(name[level:], package, level)
backend/tests/test_coordinate_validation.py:8: in <module>
    from visual_client.core.utils.coordinates import GlobalCoord, LocalCoord
E   ModuleNotFoundError: No module named 'visual_client'
_____________________ ERROR collecting tests/test_retry.py _____________________
backend/utils/retry.py:8: in <module>
    from backend.utils.logger import Logger
E   ModuleNotFoundError: No module named 'backend.utils.logger'

During handling of the above exception, another exception occurred:
../.pyenv/versions/3.11.5/lib/python3.11/site-packages/_pytest/python.py:493: in importtestmodule
    mod = import_path(
../.pyenv/versions/3.11.5/lib/python3.11/site-packages/_pytest/pathlib.py:587: in import_path
    importlib.import_module(module_name)
../.pyenv/versions/3.11.5/lib/python3.11/importlib/__init__.py:126: in import_module
    return _bootstrap._gcd_import(name[level:], package, level)
<frozen importlib._bootstrap>:1204: in _gcd_import
    ???
<frozen importlib._bootstrap>:1176: in _find_and_load
    ???
<frozen importlib._bootstrap>:1147: in _find_and_load_unlocked
    ???
<frozen importlib._bootstrap>:690: in _load_unlocked
    ???
../.pyenv/versions/3.11.5/lib/python3.11/site-packages/_pytest/assertion/rewrite.py:185: in exec_module
    exec(co, module.__dict__)
backend/tests/test_retry.py:5: in <module>
    from backend.utils.retry import retry, retry_sync, retry_async, RetryOptions
backend/utils/retry.py:10: in <module>
    from app.src.core.utils.logger import Logger
E     File "/Users/Sharrone/Visual_DM/backend/app/src/core/utils/logger.py", line 5
E       /**
E       ^
E   SyntaxError: invalid syntax
=============================== warnings summary ===============================
../.pyenv/versions/3.11.5/lib/python3.11/site-packages/pydantic/_internal/_config.py:323
  /Users/Sharrone/.pyenv/versions/3.11.5/lib/python3.11/site-packages/pydantic/_internal/_config.py:323: PydanticDeprecatedSince20: Support for class-based `config` is deprecated, use ConfigDict instead. Deprecated in Pydantic V2.0 to be removed in V3.0. See Pydantic V2 Migration Guide at https://errors.pydantic.dev/2.11/migration/
    warnings.warn(DEPRECATION_MESSAGE, DeprecationWarning)

backend/tests/test_async_function_patterns.py:112
  /Users/Sharrone/Visual_DM/backend/tests/test_async_function_patterns.py:112: PytestUnknownMarkWarning: Unknown pytest.mark.asyncio - is this a typo?  You can register custom marks to avoid this warning - for details, see https://docs.pytest.org/en/stable/how-to/mark.html
    @pytest.mark.asyncio

backend/tests/test_async_function_patterns.py:118
  /Users/Sharrone/Visual_DM/backend/tests/test_async_function_patterns.py:118: PytestUnknownMarkWarning: Unknown pytest.mark.asyncio - is this a typo?  You can register custom marks to avoid this warning - for details, see https://docs.pytest.org/en/stable/how-to/mark.html
    @pytest.mark.asyncio

backend/tests/test_async_function_patterns.py:126
  /Users/Sharrone/Visual_DM/backend/tests/test_async_function_patterns.py:126: PytestUnknownMarkWarning: Unknown pytest.mark.asyncio - is this a typo?  You can register custom marks to avoid this warning - for details, see https://docs.pytest.org/en/stable/how-to/mark.html
    @pytest.mark.asyncio

backend/tests/test_async_function_patterns.py:143
  /Users/Sharrone/Visual_DM/backend/tests/test_async_function_patterns.py:143: PytestUnknownMarkWarning: Unknown pytest.mark.asyncio - is this a typo?  You can register custom marks to avoid this warning - for details, see https://docs.pytest.org/en/stable/how-to/mark.html
    @pytest.mark.asyncio

backend/tests/test_async_function_patterns.py:151
  /Users/Sharrone/Visual_DM/backend/tests/test_async_function_patterns.py:151: PytestUnknownMarkWarning: Unknown pytest.mark.asyncio - is this a typo?  You can register custom marks to avoid this warning - for details, see https://docs.pytest.org/en/stable/how-to/mark.html
    @pytest.mark.asyncio

backend/tests/test_async_function_patterns.py:157
  /Users/Sharrone/Visual_DM/backend/tests/test_async_function_patterns.py:157: PytestUnknownMarkWarning: Unknown pytest.mark.asyncio - is this a typo?  You can register custom marks to avoid this warning - for details, see https://docs.pytest.org/en/stable/how-to/mark.html
    @pytest.mark.asyncio

backend/tests/test_async_function_patterns.py:164
  /Users/Sharrone/Visual_DM/backend/tests/test_async_function_patterns.py:164: PytestUnknownMarkWarning: Unknown pytest.mark.asyncio - is this a typo?  You can register custom marks to avoid this warning - for details, see https://docs.pytest.org/en/stable/how-to/mark.html
    @pytest.mark.asyncio

backend/tests/test_async_function_patterns.py:170
  /Users/Sharrone/Visual_DM/backend/tests/test_async_function_patterns.py:170: PytestUnknownMarkWarning: Unknown pytest.mark.asyncio - is this a typo?  You can register custom marks to avoid this warning - for details, see https://docs.pytest.org/en/stable/how-to/mark.html
    @pytest.mark.asyncio

backend/tests/test_async_function_patterns.py:176
  /Users/Sharrone/Visual_DM/backend/tests/test_async_function_patterns.py:176: PytestUnknownMarkWarning: Unknown pytest.mark.asyncio - is this a typo?  You can register custom marks to avoid this warning - for details, see https://docs.pytest.org/en/stable/how-to/mark.html
    @pytest.mark.asyncio

backend/tests/test_async_function_patterns.py:194
  /Users/Sharrone/Visual_DM/backend/tests/test_async_function_patterns.py:194: PytestUnknownMarkWarning: Unknown pytest.mark.asyncio - is this a typo?  You can register custom marks to avoid this warning - for details, see https://docs.pytest.org/en/stable/how-to/mark.html
    @pytest.mark.asyncio

-- Docs: https://docs.pytest.org/en/stable/how-to/capture-warnings.html
=========================== short test summary info ============================
ERROR backend/app/src/core/visualdm_core/tests/test_cloud_storage.py
ERROR backend/app/world/tests/test_region.py
ERROR backend/combat/tests/test_damage_composition.py
ERROR backend/core/managers/tests/test_robust_scene_manager.py
ERROR backend/core2/models/test_item_attributes.py
ERROR backend/python_converted/src/worldgen/core/test_deterministic_rng.py
ERROR backend/python_converted/src/worldgen/environment/__tests__/test_biome_transitions.py
ERROR backend/regions/test_region_revolt_utils.py
ERROR backend/tests/test_coordinate_validation.py
ERROR backend/tests/test_retry.py
!!!!!!!!!!!!!!!!!!! Interrupted: 10 errors during collection !!!!!!!!!!!!!!!!!!!
================= 28 skipped, 11 warnings, 10 errors in 2.32s ==================
